<?xml version="1.0" ?>
<!-- =================================================================================== -->
<!-- |    This document was autogenerated by xacro from arm.xacro                      | -->
<!-- |    EDITING THIS FILE BY HAND IS NOT RECOMMENDED                                 | -->
<!-- =================================================================================== -->
<robot name="arm">
  <!-- urdf generated using xacro files -->

  <!-- materials -->
  <material name="red">
    <color rgba="0 1 0 1"/>
  </material>
  <material name="white">
    <color rgba="1 1 1 1"/>
  </material>
  <material name="blue">
    <color rgba="0 0 1 1"/>
  </material>
  <material name="black">
    <color rgba="0 0 0 1"/>
  </material>
  <!-- base_link -->
  <link name="base_link"/>
  <joint name="base_joint" type="fixed">
    <parent link="base_link"/>
    <child link="bodylink_1"/>
    <origin xyz="0 0 0"/>
  </joint>
  <!-- body link 1st -->
  <link name="bodylink_1">
    <visual>
      <origin xyz="0 0 0.1"/>
      <geometry>
        <box size="0.25 0.35 0.2"/>
      </geometry>
      <material name="blue"/>
    </visual>
    <collision>
      <origin xyz="0 0 0"/>
      <geometry>
        <box size="0.25 0.35 0"/>
      </geometry>
    </collision>
    <inertial>
      <origin rpy="0 0 0" xyz="0 0 0.15"/>
      <mass value="0.5"/>
      <inertia ixx="0.0005666666666666667" ixy="0.0" ixz="0.0" iyy="0.001816666666666667" iyz="0.0" izz="0.0020833333333333337"/>
    </inertial>
  </link>
  <!-- body joint 1st -->
  <joint name="bodyjoint_1" type="revolute">
    <parent link="bodylink_1"/>
    <child link="bodylink_2"/>
    <origin rpy="0 0 0" xyz="0 0 0.2"/>
    <axis xyz="0 1 0"/>
    <limit effort="10" lower="-90" upper="90" velocity="5"/>
  </joint>
  <!--body link 2nd-->
  <link name="bodylink_2">
    <visual>
      <origin xyz="0 0 0.4"/>
      <geometry>
        <box size="0.25 0.35 0.8"/>
      </geometry>
      <material name="red"/>
    </visual>
    <collision>
      <origin xyz="0 0 0.4"/>
      <geometry>
        <box size="0.25 0.35 0.55"/>
      </geometry>
    </collision>
    <inertial>
      <origin rpy="0 0 0" xyz="0 0 1"/>
      <mass value="0.5"/>
      <inertia ixx="0.0005666666666666667" ixy="0.0" ixz="0.0" iyy="0.001816666666666667" iyz="0.0" izz="0.0020833333333333337"/>
    </inertial>
  </link>
  <!-- body joint 2nd -->
  <joint name="bodyjoint_2" type="revolute">
    <parent link="bodylink_2"/>
    <child link="bodylink_3"/>
    <!--origin xyz="0 0 1" rpy="-${pi/2} 0 0" /-->
    <origin rpy="0 0 0" xyz="0 0 0.8"/>
    <axis xyz="0 1 0"/>
    <limit effort="10" lower="-90" upper="90" velocity="5"/>
  </joint>
  <!--body link 3rd-->
  <link name="bodylink_3">
    <visual>
      <origin xyz="0 0 0.4"/>
      <geometry>
        <box size="0.25 0.35 0.8"/>
      </geometry>
      <material name="blue"/>
    </visual>
    <collision>
      <origin xyz="0 0 0.4"/>
      <geometry>
        <box size="0.25 0.35 0.55"/>
      </geometry>
    </collision>
    <inertial>
      <origin rpy="0 0 0" xyz="0 0 1"/>
      <mass value="0.5"/>
      <inertia ixx="0.0005666666666666667" ixy="0.0" ixz="0.0" iyy="0.001816666666666667" iyz="0.0" izz="0.0020833333333333337"/>
    </inertial>
  </link>
  <!-- body joint 3rd -->
  <joint name="bodyjoint_3" type="revolute">
    <parent link="bodylink_3"/>
    <child link="bodylink_4"/>
    <origin rpy="0 0 0" xyz="0 0 0.8"/>
    <axis xyz="0 1 0"/>
    <limit effort="10" lower="-90" upper="90" velocity="5"/>
  </joint>
  <!--body link 4th-->
  <link name="bodylink_4">
    <visual>
      <origin xyz="0 0 0.45"/>
      <geometry>
        <box size="0.25 0.35 0.9"/>
      </geometry>
      <material name="red"/>
    </visual>
    <collision>
      <origin xyz="0 0 0.45"/>
      <geometry>
        <box size="0.25 0.35 0.65"/>
      </geometry>
    </collision>
    <inertial>
      <origin rpy="0 0 0" xyz="0 0 1"/>
      <mass value="0.5"/>
      <inertia ixx="0.0005666666666666667" ixy="0.0" ixz="0.0" iyy="0.001816666666666667" iyz="0.0" izz="0.0020833333333333337"/>
    </inertial>
  </link>
  <!-- include camera xacro (사용자 필요 시) -->
  <!--xacro:include filename="lidar.xacro"/>
    <xacro:include filename="gazebo.xacro"/-->
</robot>
